Workbook
Name Exp_Type: #REF!
Name Expenditure_Type: #REF!
Name ExpTypes: #REF!

Sheet Non staff expense form
A1: Non-Staff Expenses Form
A2: All forms must be submitted directly from your department in Excel format, by email, to expenses@contacts.bham.ac.uk All fields marked * are mandatory; if you don't complete these fields, we cannot process the form. Complete the form electronically as handwritten submissions will not be accepted.
A4: DATE * | C4: 45633
A5: FIRST NAME * | C5: FARAN
A6: LAST NAME * | C6: ZAFAR
A7: ADDRESS * | C7: FLAT 116 IQ STUDENT ACCOMODATION
A8: POST CODE * | C8: B47AG
A9: TELEPHONE NUMBER * | C9: 07355889332
A10: EMAIL ADDRESS * | C10: faranzafarcs@gmail.com
A11: STUDENT ID.. | C11: 50036860
A12: DESCRIPTION OF THE CLAIM *
A14: We can pay expenses into either a UK or non-UK bank account. Please fill in the form with the bank details of the account you want us to pay the expenses to.
A16: UK BANK ACCOUNT DETAILS
A18: BANK NAME * | C18: Nationwide
A20: ACCOUNT NUMBER * | C20: 2 | D20: 8 | G20: 4 | K20: 8 | N20: 9 | Q20: 2 | S20: 9 | W20: 0
A22: SORT CODE * | C22: 0 | D22: 7 | K22: 0 | N22: 8 | S22: 0 | W22: 6
A24: ** Bank details are the sole responsibility of the person completing the claim form **
A26: NON-UK BANK ACCOUNT DETAILS
A28: COUNTRY *
A29: BANK NAME *
A30: IBAN / ACCOUNT NUMBER *
A31: SWIFT / BIC *
A32: IFSC / BSB CODE
A33: INSTITUTION NUMBER. | AA33: TRANSIT NUMBER
A34: ABA ROUTING NUMBER
A35: INTERMEDIARY BANK DETAILS (SWIFT / BIC)
A37: EXPENSE ITEMS
A39: ** Receipts for expenses items must be attached to the email with this form. We cannot process expenses without receipts. **
A41: Expense Description | K41: Company | Q41: Analysis | V41: Cost Centre | Z41: Activity | AC41: Source of Funds | AI41: Intercompany | AN41: Spare | AR41: Currency | AS41: Amount
AI42: 00 | AN42: 00000
AI43: 00 | AN43: 00000
AI44: 00 | AN44: 00000
AI45: 00 | AN45: 00000
AI46: 00 | AN46: 00000
AI47: 00 | AN47: 00000
AI48: 00 | AN48: 00000
AI49: 00 | AN49: 00000
AI50: 00 | AN50: 00000
AI51: 00 | AN51: 00000
AI52: 00 | AN52: 00000
...

Sheet Translator
A2: Invoice number | B2: {=+B6&" "&IF('Non staff expense form'!C11:AB11<>"",'Non staff expense form'!C11:AB11&" ","")&Translator!AS5} -> FARAN ZAFAR 50036860 07.12.24 | C2: FARAN ZAFAR 07.12.24 | D2: FARAN ZAFAR 07.12.24 | E2: FARAN ZAFAR 07.12.24 | F2: FARAN ZAFAR 07.12.24 | G2: FARAN ZAFAR 07.12.24 | H2: FARAN ZAFAR 07.12.24 | I2: FARAN ZAFAR 07.12.24 | J2: FARAN ZAFAR 07.12.24 | K2: FARAN ZAFAR 07.12.24 | L2: FARAN ZAFAR 07.12.24 | M2: FARAN ZAFAR 07.12.24 | N2: FARAN ZAFAR 07.12.24 | O2: FARAN ZAFAR 07.12.24 | P2: FARAN ZAFAR 07.12.24 | Q2: FARAN ZAFAR 07.12.24 | R2: FARAN ZAFAR 07.12.24 | S2: FARAN ZAFAR 07.12.24 | T2: FARAN ZAFAR 07.12.24 | U2: FARAN ZAFAR 07.12.24 | V2: FARAN ZAFAR 07.12.24 | W2: FARAN ZAFAR 07.12.24 | X2: FARAN ZAFAR 07.12.24 | Y2: FARAN ZAFAR 07.12.24 | Z2: FARAN ZAFAR 07.12.24 | AA2: FARAN ZAFAR 07.12.24
A3: Currency | B3: {=+'Non staff expense form'!C86:AS86} -> 0 | C3: 0 | D3: 0 | E3: 0 | F3: 0 | G3: 0 | H3: 0 | I3: 0 | J3: 0 | K3: 0 | L3: 0 | M3: 0 | N3: 0 | O3: 0 | P3: 0 | Q3: 0 | R3: 0 | S3: 0 | T3: 0 | U3: 0 | V3: 0 | W3: 0 | X3: 0 | Y3: 0 | Z3: 0 | AA3: 0 | AB3: 0 | AC3: 0 | AD3: 0 | AE3: 0 | AF3: 0 | AG3: 0 | AH3: 0 | AI3: 0 | AJ3: 0 | AK3: 0 | AL3: 0 | AM3: 0 | AN3: 0 | AO3: 0 | AP3: 0 | AQ3: 0 | AR3: 0
A4: Amount | B4: {=+'Non staff expense form'!C87:AS87} -> 0 | C4: 0 | D4: 0 | E4: 0 | F4: 0 | G4: 0 | H4: 0 | I4: 0 | J4: 0 | K4: 0 | L4: 0 | M4: 0 | N4: 0 | O4: 0 | P4: 0 | Q4: 0 | R4: 0 | S4: 0 | T4: 0 | U4: 0 | V4: 0 | W4: 0 | X4: 0 | Y4: 0 | Z4: 0 | AA4: 0 | AB4: 0 | AC4: 0 | AD4: 0 | AE4: 0 | AF4: 0 | AG4: 0 | AH4: 0 | AI4: 0 | AJ4: 0 | AK4: 0 | AL4: 0 | AM4: 0 | AN4: 0 | AO4: 0 | AP4: 0 | AQ4: 0 | AR4: 0
A5: Date | B5: {=+'Non staff expense form'!C4:AS4} -> 45633 | C5: 0 | D5: 0 | E5: 0 | F5: 0 | G5: 0 | H5: 0 | I5: 0 | J5: 0 | K5: 0 | L5: 0 | M5: 0 | N5: 0 | O5: 0 | P5: 0 | Q5: 0 | R5: 0 | S5: 0 | T5: 0 | U5: 0 | V5: 0 | W5: 0 | X5: 0 | Y5: 0 | Z5: 0 | AA5: 0 | AB5: 0 | AC5: 0 | AD5: 0 | AE5: 0 | AF5: 0 | AG5: 0 | AH5: 0 | AI5: 0 | AJ5: 0 | AK5: 0 | AL5: 0 | AM5: 0 | AN5: 0 | AO5: 0 | AP5: 0 | AQ5: 0 | AR5: 0 | AS5: =TEXT(B5, "dd.mm.yy") -> 07.12.24
A6: Full name | B6: {=+'Non staff expense form'!C5:AS5&" "&'Non staff expense form'!C6:AS6} -> FARAN ZAFAR
A7: Email | B7: {=+'Non staff expense form'!C10:AB10} -> faranzafarcs@gmail.com | C7: 0 | D7: 0 | E7: 0 | F7: 0 | G7: 0 | H7: 0 | I7: 0 | J7: 0 | K7: 0 | L7: 0 | M7: 0 | N7: 0 | O7: 0 | P7: 0 | Q7: 0 | R7: 0 | S7: 0 | T7: 0 | U7: 0 | V7: 0 | W7: 0 | X7: 0 | Y7: 0 | Z7: 0 | AA7: 0
A8: Description of the claim | B8: {=+'Non staff expense form'!C12:AS12} -> 0 | C8: 0 | D8: 0 | E8: 0 | F8: 0 | G8: 0 | H8: 0 | I8: 0 | J8: 0 | K8: 0 | L8: 0 | M8: 0 | N8: 0 | O8: 0 | P8: 0 | Q8: 0 | R8: 0 | S8: 0 | T8: 0 | U8: 0 | V8: 0 | W8: 0 | X8: 0 | Y8: 0 | Z8: 0 | AA8: 0 | AB8: 0 | AC8: 0 | AD8: 0 | AE8: 0 | AF8: 0 | AG8: 0 | AH8: 0 | AI8: 0 | AJ8: 0 | AK8: 0 | AL8: 0 | AM8: 0 | AN8: 0 | AO8: 0 | AP8: 0 | AQ8: 0 | AR8: 0
A10: GL
B12: Amount | C12: Currency | F12: Coding | V12: Description
A13: Expense 1 | B13: =+'Non staff expense form'!AS42 -> 0 | C13: =+'Non staff expense form'!AR42 -> 0 | F13: {='Non staff expense form'!K42:P42&"."&'Non staff expense form'!Q42:U42&"."&'Non staff expense form'!V42:Y42&"."&'Non staff expense form'!Z42:AB42&"."&'Non staff expense form'!AC42:AH42&".00.000000"} -> .....00.000000 | G13: .....00.000000 | H13: .....00.000000 | I13: #N/A | J13: #N/A | K13: #N/A | V13: {='Non staff expense form'!A42:I42} -> 0 | W13: 0 | X13: 0 | Y13: 0 | Z13: 0 | AA13: 0 | AB13: 0 | AC13: 0 | AD13: 0
A14: Expense 2 | B14: =+'Non staff expense form'!AS43 -> 0 | C14: =+'Non staff expense form'!AR43 -> 0 | F14: {='Non staff expense form'!K43:P43&"."&'Non staff expense form'!Q43:U43&"."&'Non staff expense form'!V43:Y43&"."&'Non staff expense form'!Z43:AB43&"."&'Non staff expense form'!AC43:AH43&".00.000000"} -> .....00.000000 | G14: .....00.000000 | H14: .....00.000000 | I14: #N/A | J14: #N/A | K14: #N/A | V14: {='Non staff expense form'!A43:I43} -> 0 | W14: 0 | X14: 0 | Y14: 0 | Z14: 0 | AA14: 0 | AB14: 0 | AC14: 0 | AD14: 0
A15: Expense 3 | B15: =+'Non staff expense form'!AS44 -> 0 | C15: =+'Non staff expense form'!AR44 -> 0 | F15: {='Non staff expense form'!K44:P44&"."&'Non staff expense form'!Q44:U44&"."&'Non staff expense form'!V44:Y44&"."&'Non staff expense form'!Z44:AB44&"."&'Non staff expense form'!AC44:AH44&".00.000000"} -> .....00.000000 | G15: .....00.000000 | H15: .....00.000000 | I15: #N/A | J15: #N/A | K15: #N/A | V15: {='Non staff expense form'!A44:I44} -> 0 | W15: 0 | X15: 0 | Y15: 0 | Z15: 0 | AA15: 0 | AB15: 0 | AC15: 0 | AD15: 0
A16: Expense 4 | B16: =+'Non staff expense form'!AS45 -> 0 | C16: =+'Non staff expense form'!AR45 -> 0 | F16: {='Non staff expense form'!K45:P45&"."&'Non staff expense form'!Q45:U45&"."&'Non staff expense form'!V45:Y45&"."&'Non staff expense form'!Z45:AB45&"."&'Non staff expense form'!AC45:AH45&".00.000000"} -> .....00.000000 | G16: .....00.000000 | H16: .....00.000000 | I16: #N/A | J16: #N/A | K16: #N/A | V16: {='Non staff expense form'!A45:I45} -> 0 | W16: 0 | X16: 0 | Y16: 0 | Z16: 0 | AA16: 0 | AB16: 0 | AC16: 0 | AD16: 0
A17: Expense 5 | B17: =+'Non staff expense form'!AS46 -> 0 | C17: =+'Non staff expense form'!AR46 -> 0 | F17: {='Non staff expense form'!K46:P46&"."&'Non staff expense form'!Q46:U46&"."&'Non staff expense form'!V46:Y46&"."&'Non staff expense form'!Z46:AB46&"."&'Non staff expense form'!AC46:AH46&".00.000000"} -> .....00.000000 | G17: .....00.000000 | H17: .....00.000000 | I17: #N/A | J17: #N/A | K17: #N/A | V17: {='Non staff expense form'!A46:I46} -> 0 | W17: 0 | X17: 0 | Y17: 0 | Z17: 0 | AA17: 0 | AB17: 0 | AC17: 0 | AD17: 0
A18: Expense 6 | B18: =+'Non staff expense form'!AS47 -> 0 | C18: =+'Non staff expense form'!AR47 -> 0 | F18: {='Non staff expense form'!K47:P47&"."&'Non staff expense form'!Q47:U47&"."&'Non staff expense form'!V47:Y47&"."&'Non staff expense form'!Z47:AB47&"."&'Non staff expense form'!AC47:AH47&".00.000000"} -> .....00.000000 | G18: .....00.000000 | H18: .....00.000000 | I18: #N/A | J18: #N/A | K18: #N/A | V18: {='Non staff expense form'!A47:I47} -> 0 | W18: 0 | X18: 0 | Y18: 0 | Z18: 0 | AA18: 0 | AB18: 0 | AC18: 0 | AD18: 0
A19: Expense 7 | B19: =+'Non staff expense form'!AS48 -> 0 | C19: =+'Non staff expense form'!AR48 -> 0 | F19: {='Non staff expense form'!K48:P48&"."&'Non staff expense form'!Q48:U48&"."&'Non staff expense form'!V48:Y48&"."&'Non staff expense form'!Z48:AB48&"."&'Non staff expense form'!AC48:AH48&".00.000000"} -> .....00.000000 | G19: .....00.000000 | H19: .....00.000000 | I19: #N/A | J19: #N/A | K19: #N/A | V19: {='Non staff expense form'!A48:I48} -> 0 | W19: 0 | X19: 0 | Y19: 0 | Z19: 0 | AA19: 0 | AB19: 0 | AC19: 0 | AD19: 0
A20: Expense 8 | B20: =+'Non staff expense form'!AS49 -> 0 | C20: =+'Non staff expense form'!AR49 -> 0 | F20: {='Non staff expense form'!K49:P49&"."&'Non staff expense form'!Q49:U49&"."&'Non staff expense form'!V49:Y49&"."&'Non staff expense form'!Z49:AB49&"."&'Non staff expense form'!AC49:AH49&".00.000000"} -> .....00.000000 | G20: .....00.000000 | H20: .....00.000000 | I20: #N/A | J20: #N/A | K20: #N/A | V20: {='Non staff expense form'!A49:I49} -> 0 | W20: 0 | X20: 0 | Y20: 0 | Z20: 0 | AA20: 0 | AB20: 0 | AC20: 0 | AD20: 0
A21: Expense 9 | B21: =+'Non staff expense form'!AS50 -> 0 | C21: =+'Non staff expense form'!AR50 -> 0 | F21: {='Non staff expense form'!K50:P50&"."&'Non staff expense form'!Q50:U50&"."&'Non staff expense form'!V50:Y50&"."&'Non staff expense form'!Z50:AB50&"."&'Non staff expense form'!AC50:AH50&".00.000000"} -> .....00.000000 | G21: .....00.000000 | H21: .....00.000000 | I21: #N/A | J21: #N/A | K21: #N/A | V21: {='Non staff expense form'!A50:I50} -> 0 | W21: 0 | X21: 0 | Y21: 0 | Z21: 0 | AA21: 0 | AB21: 0 | AC21: 0 | AD21: 0
A22: Expense 10 | B22: =+'Non staff expense form'!AS51 -> 0 | C22: =+'Non staff expense form'!AR51 -> 0 | F22: {='Non staff expense form'!K51:P51&"."&'Non staff expense form'!Q51:U51&"."&'Non staff expense form'!V51:Y51&"."&'Non staff expense form'!Z51:AB51&"."&'Non staff expense form'!AC51:AH51&".00.000000"} -> .....00.000000 | G22: .....00.000000 | H22: .....00.000000 | I22: #N/A | J22: #N/A | K22: #N/A | V22: {='Non staff expense form'!A51:I51} -> 0 | W22: 0 | X22: 0 | Y22: 0 | Z22: 0 | AA22: 0 | AB22: 0 | AC22: 0 | AD22: 0
A23: Expense 11 | B23: =+'Non staff expense form'!AS52 -> 0 | C23: =+'Non staff expense form'!AR52 -> 0 | F23: {='Non staff expense form'!K52:P52&"."&'Non staff expense form'!Q52:U52&"."&'Non staff expense form'!V52:Y52&"."&'Non staff expense form'!Z52:AB52&"."&'Non staff expense form'!AC52:AH52&".00.000000"} -> .....00.000000 | G23: .....00.000000 | H23: .....00.000000 | I23: #N/A | J23: #N/A | K23: #N/A | V23: {='Non staff expense form'!A52:I52} -> 0 | W23: 0 | X23: 0 | Y23: 0 | Z23: 0 | AA23: 0 | AB23: 0 | AC23: 0 | AD23: 0
A24: Expense 12 | B24: =+'Non staff expense form'!AS53 -> 0 | C24: =+'Non staff expense form'!AR53 -> 0 | F24: {='Non staff expense form'!K53:P53&"."&'Non staff expense form'!Q53:U53&"."&'Non staff expense form'!V53:Y53&"."&'Non staff expense form'!Z53:AB53&"."&'Non staff expense form'!AC53:AH53&".00.000000"} -> .....00.000000 | G24: .....00.000000 | H24: .....00.000000 | I24: #N/A | J24: #N/A | K24: #N/A | V24: {='Non staff expense form'!A53:I53} -> 0 | W24: 0 | X24: 0 | Y24: 0 | Z24: 0 | AA24: 0 | AB24: 0 | AC24: 0 | AD24: 0
... A27: Expense 15 | B27: =+'Non staff expense form'!AS56 -> 0 | C27: =+'Non staff expense form'!AR56 -> 0 | F27: {='Non staff expense form'!K56:P56&"."&'Non staff expense form'!Q56:U56&"."&'Non staff expense form'!V56:Y56&"."&'Non staff expense form'!Z56:AB56&"."&'Non staff expense form'!AC56:AH56&".00.000000"} -> .....00.000000 | G27: .....00.000000 | H27: .....00.000000 | I27: #N/A | J27: #N/A | K27: #N/A | V27: {='Non staff expense form'!A56:I56} -> 0 | W27: 0 | X27: 0 | Y27: 0 | Z27: 0 | AA27: 0 | AB27: 0 | AC27: 0 | AD27: 0
A29: PROJECT
B31: Amount | C31: Currency | F31: Description | V31: Projects | AB31: Task number | AG31: Expenditure type | AS31: Expenditure Organization
A32: Expense 1 | B32: =+'Non staff expense form'!AS59 -> 0 | C32: =+'Non staff expense form'!AR59 -> 0 | F32: {=+'Non staff expense form'!A59:I59} -> 0 | G32: 0 | H32: 0 | I32: 0 | J32: 0 | K32: 0 | L32: 0 | M32: 0 | N32: 0 | V32: {=+'Non staff expense form'!K59:P59} -> 0 | W32: 0 | X32: 0 | Y32: 0 | Z32: 0 | AA32: 0 | AB32: {=+'Non staff expense form'!Q59:U59} -> 0 | AC32: 0 | AD32: 0 | AE32: 0 | AF32: 0 | AG32: {=+'Non staff expense form'!V59:AG59} -> 0 | AH32: 0 | AI32: 0 | AJ32: 0 | AK32: 0 | AL32: 0 | AM32: 0 | AN32: 0 | AO32: 0 | AP32: 0 | AQ32: 0 | AR32: 0 | AS32: {=+'Non staff expense form'!AH59:AP59} -> 0 | AT32: 0 | AU32: 0 | AV32: 0 | AW32: 0 | AX32: 0 | AY32: 0 | AZ32: 0 | BA32: 0
A33: Expense 2 | B33: =+'Non staff expense form'!AS60 -> 0 | C33: =+'Non staff expense form'!AR60 -> 0 | F33: {=+'Non staff expense form'!A60:I60} -> 0 | G33: 0 | H33: 0 | I33: 0 | J33: 0 | K33: 0 | L33: 0 | M33: 0 | N33: 0 | V33: {=+'Non staff expense form'!K60:P60} -> 0 | W33: 0 | X33: 0 | Y33: 0 | Z33: 0 | AA33: 0 | AB33: {=+'Non staff expense form'!Q60:U60} -> 0 | AC33: 0 | AD33: 0 | AE33: 0 | AF33: 0 | AG33: {=+'Non staff expense form'!V60:AG60} -> 0 | AH33: 0 | AI33: 0 | AJ33: 0 | AK33: 0 | AL33: 0 | AM33: 0 | AN33: 0 | AO33: 0 | AP33: 0 | AQ33: 0 | AR33: 0 | AS33: {=+'Non staff expense form'!AH60:AP60} -> 0 | AT33: 0 | AU33: 0 | AV33: 0 | AW33: 0 | AX33: 0 | AY33: 0 | AZ33: 0 | BA33: 0
A34: Expense 3 | B34: =+'Non staff expense form'!AS61 -> 0 | C34: =+'Non staff expense form'!AR61 -> 0 | F34: {=+'Non staff expense form'!A61:I61} -> 0 | G34: 0 | H34: 0 | I34: 0 | J34: 0 | K34: 0 | L34: 0 | M34: 0 | N34: 0 | V34: {=+'Non staff expense form'!K61:P61} -> 0 | W34: 0 | X34: 0 | Y34: 0 | Z34: 0 | AA34: 0 | AB34: {=+'Non staff expense form'!Q61:U61} -> 0 | AC34: 0 | AD34: 0 | AE34: 0 | AF34: 0 | AG34: {=+'Non staff expense form'!V61:AG61} -> 0 | AH34: 0 | AI34: 0 | AJ34: 0 | AK34: 0 | AL34: 0 | AM34: 0 | AN34: 0 | AO34: 0 | AP34: 0 | AQ34: 0 | AR34: 0 | AS34: {=+'Non staff expense form'!AH61:AP61} -> 0 | AT34: 0 | AU34: 0 | AV34: 0 | AW34: 0 | AX34: 0 | AY34: 0 | AZ34: 0 | BA34: 0
A35: Expense 4 | B35: =+'Non staff expense form'!AS62 -> 0 | C35: =+'Non staff expense form'!AR62 -> 0 | F35: {=+'Non staff expense form'!A62:I62} -> 0 | G35: 0 | H35: 0 | I35: 0 | J35: 0 | K35: 0 | L35: 0 | M35: 0 | N35: 0 | V35: {=+'Non staff expense form'!K62:P62} -> 0 | W35: 0 | X35: 0 | Y35: 0 | Z35: 0 | AA35: 0 | AB35: {=+'Non staff expense form'!Q62:U62} -> 0 | AC35: 0 | AD35: 0 | AE35: 0 | AF35: 0 | AG35: {=+'Non staff expense form'!V62:AG62} -> 0 | AH35: 0 | AI35: 0 | AJ35: 0 | AK35: 0 | AL35: 0 | AM35: 0 | AN35: 0 | AO35: 0 | AP35: 0 | AQ35: 0 | AR35: 0 | AS35: {=+'Non staff expense form'!AH62:AP62} -> 0 | AT35: 0 | AU35: 0 | AV35: 0 | AW35: 0 | AX35: 0 | AY35: 0 | AZ35: 0 | BA35: 0
A36: Expense 5 | B36: =+'Non staff expense form'!AS63 -> 0 | C36: =+'Non staff expense form'!AR63 -> 0 | F36: {=+'Non staff expense form'!A63:I63} -> 0 | G36: 0 | H36: 0 | I36: 0 | J36: 0 | K36: 0 | L36: 0 | M36: 0 | N36: 0 | V36: {=+'Non staff expense form'!K63:P63} -> 0 | W36: 0 | X36: 0 | Y36: 0 | Z36: 0 | AA36: 0 | AB36: {=+'Non staff expense form'!Q63:U63} -> 0 | AC36: 0 | AD36: 0 | AE36: 0 | AF36: 0 | AG36: {=+'Non staff expense form'!V63:AG63} -> 0 | AH36: 0 | AI36: 0 | AJ36: 0 | AK36: 0 | AL36: 0 | AM36: 0 | AN36: 0 | AO36: 0 | AP36: 0 | AQ36: 0 | AR36: 0 | AS36: {=+'Non staff expense form'!AH63:AP63} -> 0 | AT36: 0 | AU36: 0 | AV36: 0 | AW36: 0 | AX36: 0 | AY36: 0 | AZ36: 0 | BA36: 0
A37: Expense 6 | B37: =+'Non staff expense form'!AS64 -> 0 | C37: =+'Non staff expense form'!AR64 -> 0 | F37: {=+'Non staff expense form'!A64:I64} -> 0 | G37: 0 | H37: 0 | I37: 0 | J37: 0 | K37: 0 | L37: 0 | M37: 0 | N37: 0 | V37: {=+'Non staff expense form'!K64:P64} -> 0 | W37: 0 | X37: 0 | Y37: 0 | Z37: 0 | AA37: 0 | AB37: {=+'Non staff expense form'!Q64:U64} -> 0 | AC37: 0 | AD37: 0 | AE37: 0 | AF37: 0 | AG37: {=+'Non staff expense form'!V64:AG64} -> 0 | AH37: 0 | AI37: 0 | AJ37: 0 | AK37: 0 | AL37: 0 | AM37: 0 | AN37: 0 | AO37: 0 | AP37: 0 | AQ37: 0 | AR37: 0 | AS37: {=+'Non staff expense form'!AH64:AP64} -> 0 | AT37: 0 | AU37: 0 | AV37: 0 | AW37: 0 | AX37: 0 | AY37: 0 | AZ37: 0 | BA37: 0
A38: Expense 7 | B38: =+'Non staff expense form'!AS65 -> 0 | C38: =+'Non staff expense form'!AR65 -> 0 | F38: {=+'Non staff expense form'!A65:I65} -> 0 | G38: 0 | H38: 0 | I38: 0 | J38: 0 | K38: 0 | L38: 0 | M38: 0 | N38: 0 | V38: {=+'Non staff expense form'!K65:P65} -> 0 | W38: 0 | X38: 0 | Y38: 0 | Z38: 0 | AA38: 0 | AB38: {=+'Non staff expense form'!Q65:U65} -> 0 | AC38: 0 | AD38: 0 | AE38: 0 | AF38: 0 | AG38: {=+'Non staff expense form'!V65:AG65} -> 0 | AH38: 0 | AI38: 0 | AJ38: 0 | AK38: 0 | AL38: 0 | AM38: 0 | AN38: 0 | AO38: 0 | AP38: 0 | AQ38: 0 | AR38: 0 | AS38: {=+'Non staff expense form'!AH65:AP65} -> 0 | AT38: 0 | AU38: 0 | AV38: 0 | AW38: 0 | AX38: 0 | AY38: 0 | AZ38: 0 | BA38: 0
A39: Expense 8 | B39: =+'Non staff expense form'!AS66 -> 0 | C39: =+'Non staff expense form'!AR66 -> 0 | F39: {=+'Non staff expense form'!A66:I66} -> 0 | G39: 0 | H39: 0 | I39: 0 | J39: 0 | K39: 0 | L39: 0 | M39: 0 | N39: 0 | V39: {=+'Non staff expense form'!K66:P66} -> 0 | W39: 0 | X39: 0 | Y39: 0 | Z39: 0 | AA39: 0 | AB39: {=+'Non staff expense form'!Q66:U66} -> 0 | AC39: 0 | AD39: 0 | AE39: 0 | AF39: 0 | AG39: {=+'Non staff expense form'!V66:AG66} -> 0 | AH39: 0 | AI39: 0 | AJ39: 0 | AK39: 0 | AL39: 0 | AM39: 0 | AN39: 0 | AO39: 0 | AP39: 0 | AQ39: 0 | AR39: 0 | AS39: {=+'Non staff expense form'!AH66:AP66} -> 0 | AT39: 0 | AU39: 0 | AV39: 0 | AW39: 0 | AX39: 0 | AY39: 0 | AZ39: 0 | BA39: 0
A40: Expense 9 | B40: =+'Non staff expense form'!AS67 -> 0 | C40: =+'Non staff expense form'!AR67 -> 0 | F40: {=+'Non staff expense form'!A67:I67} -> 0 | G40: 0 | H40: 0 | I40: 0 | J40: 0 | K40: 0 | L40: 0 | M40: 0 | N40: 0 | V40: {=+'Non staff expense form'!K67:P67} -> 0 | W40: 0 | X40: 0 | Y40: 0 | Z40: 0 | AA40: 0 | AB40: {=+'Non staff expense form'!Q67:U67} -> 0 | AC40: 0 | AD40: 0 | AE40: 0 | AF40: 0 | AG40: {=+'Non staff expense form'!V67:AG67} -> 0 | AH40: 0 | AI40: 0 | AJ40: 0 | AK40: 0 | AL40: 0 | AM40: 0 | AN40: 0 | AO40: 0 | AP40: 0 | AQ40: 0 | AR40: 0 | AS40: {=+'Non staff expense form'!AH67:AP67} -> 0 | AT40: 0 | AU40: 0 | AV40: 0 | AW40: 0 | AX40: 0 | AY40: 0 | AZ40: 0 | BA40: 0
A41: Expense 10 | B41: =+'Non staff expense form'!AS68 -> 0 | C41: =+'Non staff expense form'!AR68 -> 0 | F41: {=+'Non staff expense form'!A68:I68} -> 0 | G41: 0 | H41: 0 | I41: 0 | J41: 0 | K41: 0 | L41: 0 | M41: 0 | N41: 0 | V41: {=+'Non staff expense form'!K68:P68} -> 0 | W41: 0 | X41: 0 | Y41: 0 | Z41: 0 | AA41: 0 | AB41: {=+'Non staff expense form'!Q68:U68} -> 0 | AC41: 0 | AD41: 0 | AE41: 0 | AF41: 0 | AG41: {=+'Non staff expense form'!V68:AG68} -> 0 | AH41: 0 | AI41: 0 | AJ41: 0 | AK41: 0 | AL41: 0 | AM41: 0 | AN41: 0 | AO41: 0 | AP41: 0 | AQ41: 0 | AR41: 0 | AS41: {=+'Non staff expense form'!AH68:AP68} -> 0 | AT41: 0 | AU41: 0 | AV41: 0 | AW41: 0 | AX41: 0 | AY41: 0 | AZ41: 0 | BA41: 0
A42: Expense 11 | B42: =+'Non staff expense form'!AS69 -> 0 | C42: =+'Non staff expense form'!AR69 -> 0 | F42: {=+'Non staff expense form'!A69:I69} -> 0 | G42: 0 | H42: 0 | I42: 0 | J42: 0 | K42: 0 | L42: 0 | M42: 0 | N42: 0 | V42: {=+'Non staff expense form'!K69:P69} -> 0 | W42: 0 | X42: 0 | Y42: 0 | Z42: 0 | AA42: 0 | AB42: {=+'Non staff expense form'!Q69:U69} -> 0 | AC42: 0 | AD42: 0 | AE42: 0 | AF42: 0 | AG42: {=+'Non staff expense form'!V69:AG69} -> 0 | AH42: 0 | AI42: 0 | AJ42: 0 | AK42: 0 | AL42: 0 | AM42: 0 | AN42: 0 | AO42: 0 | AP42: 0 | AQ42: 0 | AR42: 0 | AS42: {=+'Non staff expense form'!AH69:AP69} -> 0 | AT42: 0 | AU42: 0 | AV42: 0 | AW42: 0 | AX42: 0 | AY42: 0 | AZ42: 0 | BA42: 0
A43: Expense 12 | B43: =+'Non staff expense form'!AS70 -> 0 | C43: =+'Non staff expense form'!AR70 -> 0 | F43: {=+'Non staff expense form'!A70:I70} -> 0 | G43: 0 | H43: 0 | I43: 0 | J43: 0 | K43: 0 | L43: 0 | M43: 0 | N43: 0 | V43: {=+'Non staff expense form'!K70:P70} -> 0 | W43: 0 | X43: 0 | Y43: 0 | Z43: 0 | AA43: 0 | AB43: {=+'Non staff expense form'!Q70:U70} -> 0 | AC43: 0 | AD43: 0 | AE43: 0 | AF43: 0 | AG43: {=+'Non staff expense form'!V70:AG70} -> 0 | AH43: 0 | AI43: 0 | AJ43: 0 | AK43: 0 | AL43: 0 | AM43: 0 | AN43: 0 | AO43: 0 | AP43: 0 | AQ43: 0 | AR43: 0 | AS43: {=+'Non staff expense form'!AH70:AP70} -> 0 | AT43: 0 | AU43: 0 | AV43: 0 | AW43: 0 | AX43: 0 | AY43: 0 | AZ43: 0 | BA43: 0
... A46: Expense 15 | B46: =+'Non staff expense form'!AS73 -> 0 | C46: =+'Non staff expense form'!AR73 -> 0 | F46: {=+'Non staff expense form'!A73:I73} -> 0 | G46: 0 | H46: 0 | I46: 0 | J46: 0 | K46: 0 | L46: 0 | M46: 0 | N46: 0 | V46: {=+'Non staff expense form'!K73:P73} -> 0 | W46: 0 | X46: 0 | Y46: 0 | Z46: 0 | AA46: 0 | AB46: {=+'Non staff expense form'!Q73:U73} -> 0 | AC46: 0 | AD46: 0 | AE46: 0 | AF46: 0 | AG46: {=+'Non staff expense form'!V73:AG73} -> 0 | AH46: 0 | AI46: 0 | AJ46: 0 | AK46: 0 | AL46: 0 | AM46: 0 | AN46: 0 | AO46: 0 | AP46: 0 | AQ46: 0 | AR46: 0 | AS46: {=+'Non staff expense form'!AH73:AP73} -> 0 | AT46: 0 | AU46: 0 | AV46: 0 | AW46: 0 | AX46: 0 | AY46: 0 | AZ46: 0 | BA46: 0
A49: UK bank details
A51: Full name | B51: {=+'Non staff expense form'!C5:AS5&" "&'Non staff expense form'!C6:AS6} -> FARAN ZAFAR
A52: Account number | B52: {='Non staff expense form'!C20&'Non staff expense form'!D20:F20&'Non staff expense form'!G20:J20&'Non staff expense form'!K20:M20&'Non staff expense form'!N20:P20&'Non staff expense form'!Q20:R20&'Non staff expense form'!S20:V20&'Non staff expense form'!W20} -> 28489290 | C52: 20 | D52: #N/A | E52: #N/A
...

Sheet Dropdown menu
A1: Vehicle | C1: Payment currencies | E1: Expense currencies | G1: Type of expense | I1: Organization
A2: CAR | C2: GBP | E2: GBP | G2: Advertising Non Staff | I2: Arts and Law
A3: MOTORCYCLE | C3: USD | E3: USD | G3: Advertising Staff | I3: Social Work and Social Care
A4: BICYCLE | C4: EUR | E4: EUR | G4: Animals Maintenance | I4: Social Policy, Sociology and Criminology
C5: AED | E5: AED | G5: Animals Purchases | I5: Maintenance Operations
C6: CAD | E6: AUD | G6: Archive Storage | I6: Maintenance Management
C7: AUD | E7: CAD | G7: Audio Visual Expenses | I7: Maintenance - Reactive
E8: CHF | G8: Audit Fee | I8: Maintenance - Planned
E9: CNY | G9: BHF Travel Fund | I9: Maintenance - Officers
E10: SEK | G10: Bank Charges | I10: Maintenance - HAS
E11: MXN | G11: Books Publications Journal Subscriptions | I11: Maintenance - Minor Works
E12: NZD | G12: Casual Staff Demonstrating fees | I12: Professional Services
E13: SGD | G13: Catering External | I13: Estates Projects
E14: HKD | G14: Catering Internal | I14: IT Services
E15: NOK | G15: Chemicals General | I15: Infrastructure Services
E16: KRW | G16: Cleaning Expenses | I16: Architecture, Security and Innovation
E17: TRY | G17: Clothing | I17: Properties and Leases
E18: INR | G18: Computing costs including licences | I18: MDS - Administration
E19: RUB | G19: Conference costs Overseas | I19: MDS - Research and Knowledge Transfer
... E27: JPY | G27: DI Facilities External | I27: Drama and Theatre Arts
G28: DI Facilities UOB | I28: English Language and Linguistics
G29: Equipment Hire Rent | I29: English Literature
G30: Equipment Maintenance | I30: Film and Creative Writing
G31: Equipment Purchase | I31: Centre for Byzantine, Ottoman and Modern Greek Studies
G32: Equipment greater than OJEC | I32: History
G33: Equipment less than £10K | I33: Ironbridge International Institute for Cultural Heritage
G34: Equipment £10K to OJEC limit | I34: African Studies and Anthropology
G35: Estates Costs Repairs and Maintenance | I35: Art History, Curating and Visual Studies
G36: Fleetcheck | I36: Engineering and Physical Sciences
G37: Furniture Costs | I37: Chemical Engineering
G38: Gases | I38: Chemistry
G39: Gases Cylinder Rental | I39: Computer Science
... G78: Visiting Lecturer's fees | I78: Management
I79: Economics
I80: Government
I81: International Development
I82: Estates
I83: English, Drama and Creative Studies
I84: History and Cultures
I85: Classics, Ancient History and Archaeology
...
